Workbook

Sheet COMPARATIVO
B1: COMPARATIVO INSUMOS
B7: ID | C7: CODIGO DE BARRAS | D7: CATALOGO/ REFERENCIA | E7: DESCRIPCIÓN | F7: CANTIDAD | G7: UMC | H7: FOREFRONT 30 días | I7: OM SOLUTION 30 días | J7: ACUMED 30 días | K7: GRS DETECCION | M7: JTC Contado | N7: QUINSA Contado | O7: ALBERTO OSORIO 30 días | P7: NADRO 30 días | Q7: MOREH 1 semana | R7: MCC FARMA 15 día | S7: LANCETA contado | T7: WALMART | U7: SALUCOM contado | V7: MIN | W7: REQUI | X7: PROVEEDOR | Y7: OC | Z7: TOTAL | AA7: ESTATUS | AB7: NOTA
B8: 95 | D8: 0 | E8: ABATELENGUAS DE MADERA INDIVIDUAL ESTERIL C/100 | F8: =VLOOKUP(B8,REQUISICIÓN!$C$9:$E$125,3,0) -> 1 | G8: BOLSA C/100 | H8: 43.6 | I8: 45 | J8: 0 | M8: 0 | N8: 215 | O8: 0 | P8: 0 | Q8: 0 | R8: 0 | S8: 0 | T8: 0 | U8: 0 | V8: =SMALL(H8:U8,COUNTIF(H8:U8,"<=0")+1) -> 43.6 | W8: =VLOOKUP(B8,REQUISICIÓN!$C$9:$G$509,5,0) -> 41
B9: 61 | C9: 7502268541699 | E9: AGUA INYECTABLE 10 ML MCA. PISA C/100 | F9: =VLOOKUP(B9,REQUISICIÓN!$C$9:$E$125,3,0) -> 1 | G9: CAJA C/100 | H9: 754.4 | I9: 754.4 | J9: 740 | K9: =7*100 -> 700 | M9: 0 | O9: 835.68 | P9: 0 | Q9: 0 | R9: 0 | S9: 0 | T9: 0 | U9: 0 | V9: =SMALL(H9:U9,COUNTIF(H9:U9,"<=0")+1) -> 700 | W9: =VLOOKUP(B9,REQUISICIÓN!$C$9:$G$509,5,0) -> 41
B10: 62 | C10: 7501125110702 | E10: AGUA INYECTABLE 500 ML MCA. PISA | F10: =VLOOKUP(B10,REQUISICIÓN!$C$9:$E$125,3,0) -> #N/A | G10: CAJA C/12 | H10: 0 | J10: 503.034 | M10: 0 | O10: 0 | P10: 0 | Q10: 0 | R10: 0 | S10: 0 | T10: 0 | U10: 0 | V10: =SMALL(H10:U10,COUNTIF(H10:U10,"<=0")+1) -> 503.034 | W10: =VLOOKUP(B10,REQUISICIÓN!$C$9:$G$509,5,0) -> #N/A
B11: 96 | D11: 0 | E11: AGUA OXIGENADA MCA. JALOMA 125ML | F11: =VLOOKUP(B11,REQUISICIÓN!$C$9:$E$125,3,0) -> #N/A | G11: PIEZA | H11: 8.5 | J11: 0 | M11: 0 | O11: 0 | P11: 0 | Q11: 0 | R11: 0 | S11: 0 | T11: 0 | U11: 0 | V11: =SMALL(H11:U11,COUNTIF(H11:U11,"<=0")+1) -> 8.5 | W11: =VLOOKUP(B11,REQUISICIÓN!$C$9:$G$509,5,0) -> #N/A
B12: 200 | D12: 0 | E12: AGUA OXIGENADA 100ML MCA. NADRO | F12: =VLOOKUP(B12,REQUISICIÓN!$C$9:$E$125,3,0) -> #N/A | G12: PIEZA | H12: 0 | J12: 0 | M12: 0 | O12: 0 | P12: 6.68 | Q12: 0 | R12: 0 | S12: 0 | T12: 0 | U12: 0 | V12: =SMALL(H12:U12,COUNTIF(H12:U12,"<=0")+1) -> 6.68 | W12: =VLOOKUP(B12,REQUISICIÓN!$C$9:$G$509,5,0) -> #N/A
B13: 246 | C13: 7501048335138 | E13: AGUA OXIGENADA 100ML MCA. PROTEC | F13: =VLOOKUP(B13,REQUISICIÓN!$C$9:$E$125,3,0) -> #N/A | G13: PIEZA | K13: 9 | V13: =SMALL(H13:U13,COUNTIF(H13:U13,"<=0")+1) -> 9 | W13: =VLOOKUP(B13,REQUISICIÓN!$C$9:$G$509,5,0) -> #N/A
B14: 206 | C14: 7501048350889 | D14: 0 | E14: AGUA OXIGENADA 480ML MCA. NADRO | F14: =VLOOKUP(B14,REQUISICIÓN!$C$9:$E$125,3,0) -> #N/A | G14: PIEZA | H14: 0 | J14: 0 | M14: 0 | O14: 0 | P14: 16.22 | Q14: 0 | R14: 0 | S14: 0 | T14: 0 | U14: 0 | V14: =SMALL(H14:U14,COUNTIF(H14:U14,"<=0")+1) -> 16.22 | W14: =VLOOKUP(B14,REQUISICIÓN!$C$9:$G$509,5,0) -> #N/A
B15: 133 | D15: 305198 | E15: AGUJA HIPODERMICA 16GX1 1/2 MCA. BD ( MORADA) C/100 | F15: =VLOOKUP(B15,REQUISICIÓN!$C$9:$E$125,3,0) -> 2 | G15: CAJA C/100 | H15: 216 | I15: 225 | J15: 280 | M15: 0 | O15: 0 | P15: 0 | Q15: 0 | R15: 0 | S15: 0 | T15: 0 | U15: 0 | V15: =SMALL(H15:U15,COUNTIF(H15:U15,"<=0")+1) -> 216 | W15: =VLOOKUP(B15,REQUISICIÓN!$C$9:$G$509,5,0) -> 41
B16: 16 | D16: 300017 | E16: AGUJA HIPODERMICA 18GX1/2 MCA. BD ( ROSA) C/100 | F16: =VLOOKUP(B16,REQUISICIÓN!$C$9:$E$125,3,0) -> #N/A | G16: CAJA C/100 | H16: 156 | J16: 208 | M16: 0 | O16: 0 | P16: 0 | Q16: 0 | R16: 0 | S16: 0 | T16: 0 | U16: 0 | V16: =SMALL(H16:U16,COUNTIF(H16:U16,"<=0")+1) -> 156 | W16: =VLOOKUP(B16,REQUISICIÓN!$C$9:$G$509,5,0) -> #N/A
B17: 151 | D17: AH-1838 | E17: AGUJA HIPODERMICA 18GX1/2 MCA. NIPRO ( ROSA) C/100 | F17: =VLOOKUP(B17,REQUISICIÓN!$C$9:$E$125,3,0) -> #N/A | G17: CAJA C/100 | H17: 0 | J17: 0 | M17: 0 | O17: 0 | P17: 0 | Q17: 0 | R17: 0 | S17: 0 | T17: 0 | U17: 0 | V17: =SMALL(H17:U17,COUNTIF(H17:U17,"<=0")+1) -> #NUM! | W17: =VLOOKUP(B17,REQUISICIÓN!$C$9:$G$509,5,0) -> #N/A
B18: 228 | D18: AGH18X38 | E18: AGUJA HIPODERMICA 18GX38MM MCA. DL( ROSA) C/100 | F18: =VLOOKUP(B18,REQUISICIÓN!$C$9:$E$125,3,0) -> #N/A | G18: CAJA C/100 | H18: 0 | I18: 0 | J18: 0 | K18: 86 | M18: 0 | N18: 0 | O18: 0 | P18: 0 | Q18: 0 | R18: 0 | S18: 0 | T18: 0 | U18: 0 | V18: =SMALL(H18:U18,COUNTIF(H18:U18,"<=0")+1) -> 86 | W18: =VLOOKUP(B18,REQUISICIÓN!$C$9:$G$509,5,0) -> #N/A
B19: 15 | D19: 301730 | E19: AGUJA HIPODERMICA 20GX32MM MCA. BD (AMARILLA) C/100 | F19: =VLOOKUP(B19,REQUISICIÓN!$C$9:$E$125,3,0) -> #N/A | G19: CAJA C/100 | H19: 135 | J19: 170 | M19: 0 | O19: 0 | P19: 0 | Q19: 0 | R19: 0 | S19: 0 | T19: 0 | U19: 0 | V19: =SMALL(H19:U19,COUNTIF(H19:U19,"<=0")+1) -> 135 | W19: =VLOOKUP(B19,REQUISICIÓN!$C$9:$G$509,5,0) -> #N/A
B20: 140 | D20: AGH20X32 | E20: AGUJA HIPODERMICA 20GX32MM MCA. DL (AMARILLA) C/100 | F20: =VLOOKUP(B20,REQUISICIÓN!$C$9:$E$125,3,0) -> #N/A | G20: CAJA C/100 | H20: 0 | J20: 85 | K20: 86 | M20: 0 | O20: 0 | P20: 0 | Q20: 0 | R20: 0 | S20: 0 | T20: 0 | U20: 0 | V20: =SMALL(H20:U20,COUNTIF(H20:U20,"<=0")+1) -> 85 | W20: =VLOOKUP(B20,REQUISICIÓN!$C$9:$G$509,5,0) -> #N/A
B21: 75 | D21: 301973 | E21: AGUJA HIPODERMICA 25GX5/8 MCA. BD C/100 | F21: =VLOOKUP(B21,REQUISICIÓN!$C$9:$E$125,3,0) -> #N/A | G21: CAJA | H21: 123.5 | J21: 0 | M21: 120.6667 | O21: 0 | P21: 0 | Q21: 0 | R21: 0 | S21: 0 | T21: 0 | U21: 0 | V21: =SMALL(H21:U21,COUNTIF(H21:U21,"<=0")+1) -> 120.6667 | W21: =VLOOKUP(B21,REQUISICIÓN!$C$9:$G$509,5,0) -> #N/A | AB21: =VLOOKUP(#REF!,REQUISICIÓN!#REF!,6,0) -> #REF!
B22: 152 | D22: AH-2518 | E22: AGUJA HIPODERMICA 25GX5/8 MCA. NIPRO (NARANJA) C/100 | F22: =VLOOKUP(B22,REQUISICIÓN!$C$9:$E$125,3,0) -> #N/A | G22: CAJA C/100 | H22: 0 | J22: 0 | M22: 0 | O22: 0 | P22: 0 | Q22: 0 | R22: 0 | S22: 0 | T22: 0 | U22: 0 | V22: =SMALL(H22:U22,COUNTIF(H22:U22,"<=0")+1) -> #NUM! | W22: =VLOOKUP(B22,REQUISICIÓN!$C$9:$G$509,5,0) -> #N/A
B23: 56 | C23: 30290326759 | D23: 0 | E23: AGUJA HIPODERMICA 31GX6MM 3ML MCA. BD C/30 | F23: =VLOOKUP(B23,REQUISICIÓN!$C$9:$E$125,3,0) -> #N/A | G23: CAJA C/30 | H23: 170.5 | J23: 0 | M23: 0 | O23: 0 | P23: 0 | Q23: 0 | R23: 0 | S23: 0 | T23: 0 | U23: 0 | V23: =SMALL(H23:U23,COUNTIF(H23:U23,"<=0")+1) -> 170.5 | W23: =VLOOKUP(B23,REQUISICIÓN!$C$9:$G$509,5,0) -> #N/A | AB23: Sala de infusión
B24: 60 | D24: 582509 | E24: AGUJA HUBER C/LINEA DE CONEXIÓN POLIPERF 20GX20MM | F24: =VLOOKUP(B24,REQUISICIÓN!$C$9:$E$125,3,0) -> #N/A | G24: =VLOOKUP(B24,REQUISICIÓN!$C$9:$F$12,4,0) -> #N/A | H24: 320 | J24: 0 | M24: 0 | O24: 0 | P24: 0 | Q24: 0 | R24: 0 | S24: 0 | T24: 0 | U24: 0 | V24: =SMALL(H24:U24,COUNTIF(H24:U24,"<=0")+1) -> 320 | W24: =VLOOKUP(B24,REQUISICIÓN!$C$9:$G$509,5,0) -> #N/A | AB24: =VLOOKUP(#REF!,REQUISICIÓN!#REF!,6,0) -> #REF!
B25: 93 | D25: 0 | E25: ALCOHOL 70% 500ML MCA. ALFAMEDICAL | F25: =VLOOKUP(B25,REQUISICIÓN!$C$9:$E$125,3,0) -> #N/A | G25: PIEZA | H25: 141.7 | J25: 55 | M25: 0 | O25: 0 | P25: 0 | Q25: 0 | R25: 0 | S25: 0 | T25: 0 | U25: 0 | V25: =SMALL(H25:U25,COUNTIF(H25:U25,"<=0")+1) -> 55 | W25: =VLOOKUP(B25,REQUISICIÓN!$C$9:$G$509,5,0) -> #N/A | AB25: Farmacia
B26: 201 | C26: 7501048350537 | D26: 0 | E26: ALCOHOL 70% 110ML MCA. NADRO | F26: =VLOOKUP(B26,REQUISICIÓN!$C$9:$E$125,3,0) -> #N/A | G26: PIEZA | O26: 0 | P26: 9.81 | Q26: 0 | R26: 0 | S26: 0 | T26: 0 | U26: 0 | V26: =SMALL(H26:U26,COUNTIF(H26:U26,"<=0")+1) -> 9.81 | W26: =VLOOKUP(B26,REQUISICIÓN!$C$9:$G$509,5,0) -> #N/A
B27: 202 | C27: 7501048351404 | D27: 0 | E27: ALCOHOL 70% 250ML MCA. NADRO | F27: =VLOOKUP(B27,REQUISICIÓN!$C$9:$E$125,3,0) -> #N/A | G27: PIEZA | P27: 28.39 | V27: =SMALL(H27:U27,COUNTIF(H27:U27,"<=0")+1) -> 28.39 | W27: =VLOOKUP(B27,REQUISICIÓN!$C$9:$G$509,5,0) -> #N/A
B28: 203 | C28: 7501048350599 | D28: 0 | E28: ALCOHOL 70% 500ML MCA. NADRO | F28: =VLOOKUP(B28,REQUISICIÓN!$C$9:$E$125,3,0) -> #N/A | G28: PIEZA | P28: 47.39 | V28: =SMALL(H28:U28,COUNTIF(H28:U28,"<=0")+1) -> 47.39 | W28: =VLOOKUP(B28,REQUISICIÓN!$C$9:$G$509,5,0) -> #N/A
B29: 247 | C29: 7501048333202 | E29: ALCOHOL 70% 500ML MCA. PROTEC | F29: =VLOOKUP(B29,REQUISICIÓN!$C$9:$E$125,3,0) -> #N/A | G29: PIEZA | K29: 49.5 | V29: =SMALL(H29:U29,COUNTIF(H29:U29,"<=0")+1) -> 49.5 | W29: =VLOOKUP(B29,REQUISICIÓN!$C$9:$G$509,5,0) -> #N/A
B30: 204 | C30: 7501048351411 | D30: 0 | E30: ALCOHOL 70% 1L MCA. NADRO | F30: =VLOOKUP(B30,REQUISICIÓN!$C$9:$E$125,3,0) -> #N/A | G30: PIEZA | P30: 92.73 | V30: =SMALL(H30:U30,COUNTIF(H30:U30,"<=0")+1) -> 92.73 | W30: =VLOOKUP(B30,REQUISICIÓN!$C$9:$G$509,5,0) -> #N/A
B31: 148 | D31: 7256901 | E31: BANDITA ADHESIVA REDONDA MCA. BSN C/100 | F31: =VLOOKUP(B31,REQUISICIÓN!$C$9:$E$125,3,0) -> 1 | G31: CAJA C/100 | H31: 73.8 | I31: 73.8 | J31: 120 | M31: 0 | N31: 36.21 | O31: 91.29 | P31: 0 | Q31: 0 | R31: 0 | S31: 0 | T31: 0 | U31: 0 | V31: =SMALL(H31:U31,COUNTIF(H31:U31,"<=0")+1) -> 36.21 | W31: =VLOOKUP(B31,REQUISICIÓN!$C$9:$G$509,5,0) -> 41
B32: 109 | C32: 7702136642286 | D32: 642296 | E32: BANDITA ADHESIVA REDONDA MCA. JALOMA C/100 | F32: =VLOOKUP(B32,REQUISICIÓN!$C$9:$E$125,3,0) -> #N/A | G32: CAJA C/100 | H32: 32.9 | M32: 0 | O32: 0 | P32: 0 | Q32: 0 | R32: 0 | S32: 0 | T32: 0 | U32: 0 | V32: =SMALL(H32:U32,COUNTIF(H32:U32,"<=0")+1) -> 32.9 | W32: =VLOOKUP(B32,REQUISICIÓN!$C$9:$G$509,5,0) -> #N/A
B33: 242 | C33: 7501048658947 | E33: BANDITA ADHESIVA MCA. PROTE C/100 | F33: =VLOOKUP(B33,REQUISICIÓN!$C$9:$E$125,3,0) -> #N/A | G33: CAJA C/100 | K33: 57 | V33: =SMALL(H33:U33,COUNTIF(H33:U33,"<=0")+1) -> 57 | W33: =VLOOKUP(B33,REQUISICIÓN!$C$9:$G$509,5,0) -> #N/A
B34: 19 | D34: 503500 | E34: BANDITA ADHESIVA REDONDA MCA. PROTEC/100 | F34: =VLOOKUP(B34,REQUISICIÓN!$C$9:$E$125,3,0) -> #N/A | G34: Caja c/50 | H34: 30.89 | M34: 0 | O34: 0 | P34: 0 | Q34: 0 | R34: 0 | S34: 0 | T34: 0 | U34: 0 | V34: =SMALL(H34:U34,COUNTIF(H34:U34,"<=0")+1) -> 30.89 | W34: =VLOOKUP(B34,REQUISICIÓN!$C$9:$G$509,5,0) -> #N/A | AB34: Farmacia
B35: 70 | D35: 0 | E35: BATA IMPERMEABLE DESECHABLE C/MANGA MCA. MORIAHT | F35: =VLOOKUP(B35,REQUISICIÓN!$C$9:$E$125,3,0) -> #N/A | G35: PIEZA | H35: 0 | J35: 115 | K35: 25 | M35: 0 | N35: 0 | O35: 30.33 | P35: 0 | Q35: 28 | R35: 0 | S35: 0 | T35: 0 | U35: 0 | V35: =SMALL(H35:U35,COUNTIF(H35:U35,"<=0")+1) -> 25 | W35: =VLOOKUP(B35,REQUISICIÓN!$C$9:$G$509,5,0) -> #N/A
B36: 154 | D36: 0 | E36: BATA P/CIRUJANO MCA. AMBIDERM NO ESTERIL | F36: =VLOOKUP(B36,REQUISICIÓN!$C$9:$E$125,3,0) -> #N/A | G36: PIEZA | H36: 0 | M36: 0 | O36: 0 | P36: 0 | Q36: 0 | R36: 0 | S36: 0 | T36: 0 | U36: 0 | V36: =SMALL(H36:U36,COUNTIF(H36:U36,"<=0")+1) -> #NUM! | W36: =VLOOKUP(B36,REQUISICIÓN!$C$9:$G$509,5,0) -> #N/A
B37: 112 | D37: MORIAHT | E37: BATA P/PACIENTE MANGA CORTA C/10 MCA. MORIAHT | F37: =VLOOKUP(B37,REQUISICIÓN!$C$9:$E$125,3,0) -> #N/A | G37: PIEZA | H37: 0 | M37: 0 | O37: 0 | P37: 0 | Q37: 115 | R37: 0 | S37: 0 | T37: 0 | U37: 0 | V37: =SMALL(H37:U37,COUNTIF(H37:U37,"<=0")+1) -> 115 | W37: =VLOOKUP(B37,REQUISICIÓN!$C$9:$G$509,5,0) -> #N/A | AB37: Carro rojo
B38: 86 | D38: LEMHIS | E38: BATA P/PACIENTE S/MANGAS | F38: =VLOOKUP(B38,REQUISICIÓN!$C$9:$E$125,3,0) -> #N/A | G38: PAQ C/10 | H38: 123 | J38: 245 | M38: 0 | O38: 0 | P38: 0 | Q38: 0 | R38: 0 | S38: 0 | T38: 0 | U38: 0 | V38: =SMALL(H38:U38,COUNTIF(H38:U38,"<=0")+1) -> 123 | W38: =VLOOKUP(B38,REQUISICIÓN!$C$9:$G$509,5,0) -> #N/A | AB38: Farmacia
B39: 134 | D39: 0 | E39: BOLSA AUTOINFLABLE DE REANIMACIÓN MCA. AMBU | F39: =VLOOKUP(B39,REQUISICIÓN!$C$9:$E$125,3,0) -> #N/A | G39: PIEZA | H39: 0 | J39: 200 | M39: 0 | O39: 0 | P39: 0 | Q39: 0 | R39: 0 | S39: 0 | T39: 0 | U39: 0 | V39: =SMALL(H39:U39,COUNTIF(H39:U39,"<=0")+1) -> 200 | W39: =VLOOKUP(B39,REQUISICIÓN!$C$9:$G$509,5,0) -> #N/A
B40: 49 | D40: 0 | E40: BOLSA DE ORINA KENGUARD 2LT | F40: =VLOOKUP(B40,REQUISICIÓN!$C$9:$E$125,3,0) -> #N/A | G40: PIEZA | H40: 103 | M40: 0 | O40: 0 | P40: 0 | Q40: 0 | R40: 0 | S40: 0 | T40: 0 | U40: 0 | V40: =SMALL(H40:U40,COUNTIF(H40:U40,"<=0")+1) -> 103 | W40: =VLOOKUP(B40,REQUISICIÓN!$C$9:$G$509,5,0) -> #N/A
B41: 20 | D41: 0 | E41: CAMPO ESTERIL 40X40CM MCA. MORIAHT | F41: =VLOOKUP(B41,REQUISICIÓN!$C$9:$E$125,3,0) -> #N/A | G41: PIEZA | H41: 25 | K41: =125/10 -> 12.5 | M41: 0 | O41: 0 | P41: 0 | Q41: 12 | R41: 0 | S41: 0 | T41: 0 | U41: 0 | V41: =SMALL(H41:U41,COUNTIF(H41:U41,"<=0")+1) -> 12 | W41: =VLOOKUP(B41,REQUISICIÓN!$C$9:$G$509,5,0) -> #N/A | AB41: Farmacia
B42: 1 | D42: 0 | E42: CÁNULA DE GUEDEL 4FR MCA. COVIDIEN | F42: =VLOOKUP(B42,REQUISICIÓN!$C$9:$E$125,3,0) -> #N/A | G42: PIEZA | H42: 31.8 | J42: 650 | M42: 0 | O42: 0 | P42: 0 | Q42: 0 | R42: 0 | S42: 0 | T42: 0 | U42: 0 | V42: =SMALL(H42:U42,COUNTIF(H42:U42,"<=0")+1) -> 31.8 | W42: =VLOOKUP(B42,REQUISICIÓN!$C$9:$G$509,5,0) -> #N/A
B43: 2 | D43: 0 | E43: CÁNULA DE GUEDEL 5FR MCA. BICAKCILAR | F43: =VLOOKUP(B43,REQUISICIÓN!$C$9:$E$125,3,0) -> #N/A | G43: PIEZA | H43: 19.2 | J43: 1975 | M43: 0 | O43: 0 | P43: 0 | Q43: 0 | R43: 0 | S43: 0 | T43: 0 | U43: 0 | V43: =SMALL(H43:U43,COUNTIF(H43:U43,"<=0")+1) -> 19.2 | W43: =VLOOKUP(B43,REQUISICIÓN!$C$9:$G$509,5,0) -> #N/A | AB43: Carro rojo
B44: 171 | D44: 0 | E44: CÁNULA DE GUEDEL 5FR MCA. COVIDIEN | F44: =VLOOKUP(B44,REQUISICIÓN!$C$9:$E$125,3,0) -> #N/A | G44: PIEZA | H44: 0 | J44: 0 | M44: 0 | O44: 0 | P44: 0 | Q44: 0 | R44: 0 | S44: 0 | T44: 0 | U44: 0 | V44: =SMALL(H44:U44,COUNTIF(H44:U44,"<=0")+1) -> #NUM! | W44: =VLOOKUP(B44,REQUISICIÓN!$C$9:$G$509,5,0) -> #N/A
B45: 3 | D45: 0 | E45: CÁNULA DE GUEDEL 6FR MCA. BICAKCILAR | F45: =VLOOKUP(B45,REQUISICIÓN!$C$9:$E$125,3,0) -> #N/A | G45: PIEZA | H45: 19.2 | J45: 27 | M45: 0 | O45: 0 | P45: 0 | Q45: 0 | R45: 0 | S45: 0 | T45: 0 | U45: 0 | V45: =SMALL(H45:U45,COUNTIF(H45:U45,"<=0")+1) -> 19.2 | W45: =VLOOKUP(B45,REQUISICIÓN!$C$9:$G$509,5,0) -> #N/A | AB45: Carro rojo
...

Sheet REQUISICIÓN
C1: REQUISICIÓN DE COMPRA
A4: Proveedor: | G4: Fecha de elaboración: | H4: 46064
A5: Tiempo de entrega: | G5: Lugar: | H5: NARVARTE
A6: Condiciones de pago: | G6: Folio: | H6: 41
A8: Partida | B8: Catalogo | C8: ID | D8: Descripción | E8: Cantidad | F8: Unidad de Medida | G8: Requi | H8: Informaciòn Tècnica
A9: 1 | B9: 0 | C9: 95 | D9: Abatelengua de madera individual bolsa c/ 100 | E9: 1 | F9: bolsa | G9: 41
A10: 2 | B10: 0 | C10: 36 | D10: Llave de 3 vías Discofix pieza caja c/50 | E10: 50 | F10: piezas | G10: 41
A11: 3 | B11: 0 | C11: 133 | D11: Aguja Hipodermica (morada) 16G c/100 | E11: 2 | F11: cajas | G11: 41
A12: 4 | B12: 0 | C12: 61 | D12: Agua Inyectable 10 mL c/100 | E12: 1 | F12: caja | G12: 41
A13: 5 | B13: 0 | C13: 66 | D13: Solución cloruro de sodio 0.9% 50 mL c/50 | E13: 1 | F13: caja | G13: 41
A14: 6 | B14: 0 | C14: 18 | D14: Tegaderm 10 x 12 cm c/50 | E14: 1 | F14: caja | G14: 41
A15: 7 | B15: 0 | C15: 17 | D15: Tegaderm I.V. apositos 6.5 x 7 cm c/100 | E15: 1 | F15: caja | G15: 41
A16: 8 | B16: 0 | C16: 40 | D16: Removedor adhesivo en toalla hollister caja c/50 | E16: 1 | F16: caja | G16: 41
A17: 9 | B17: 0 | C17: 79 | D17: Guante latex M Ambiderm esteril c/100 | E17: 1 | F17: caja | G17: 41
A18: 10 | B18: 0 | C18: 87 | D18: Cubrebocas 3 pliegues Ambiderm azul c/50 | E18: 3 | F18: cajas | G18: 41
A19: 11 | B19: 0 | C19: 37 | D19: Maxzero conector libre de aguja BD | E19: 50 | F19: piezas | G19: 41
A20: 12 | B20: 0 | C20: 84 | D20: Fundas para reposet bolsa c/ 25 | E20: 2 | F20: bolsas | G20: 41
... A25: 17 | B25: 0 | C25: 224 | D25: Cánula con filtro Sterifix B Braun 4.5 mL caja c/ 50 | E25: 1 | F25: caja | G25: 41
A30: Notas:
A33: 1.- Todo tipo de compra debera solicitarse mediante este formato.
A34: 2.- Este formato representa la necesidad de la compra de cualquier insumo o material de curaciòn.
A35: 3.- Cualquier compra quedara sustenda mediante un cuadro comparativo que sera anexado y entregado al area solicitante, esto como parte de un
A36: seguimiento a su compra.
A41: Nombre y Firma | F41: Nombre y Firma
B42: Solicitante

Sheet Hoja1
